Workbook

Sheet Petunjuk
A1: Template Import Data Pengadaan SIPITA — IT SAPM
A2: File contoh. Baris berwarna biru di setiap sheet adalah DATA CONTOH: hapus sebelum mengisi data asli.
A4: Cara pakai
A5: 1. Isi sheet Vendor terlebih dahulu (jika vendor belum ada di sistem).
A6: 2. Isi sheet Pekerjaan: satu baris = satu pengadaan. Beri setiap baris Ref Baris unik (R1, R2, ...).
A7: 3. Isi dokumen di sheet lain dan hubungkan ke pekerjaan lewat kolom Ref Pekerjaan.
A8: 4. Upload di menu Import SIPITA, periksa pratinjau, lalu klik Simpan.
A9: 5. Baris ERROR ditolak; baris PERINGATAN tetap masuk dan ditandai 'belum lengkap'.
A11: Keterangan warna
A12: Header biru tua | B12: Kolom wajib (bertanda *)
A13: Header biru muda | B13: Kolom opsional
A14: Kolom abu-abu | B14: Dihitung otomatis (rumus). Jangan diisi; sistem menghitung ulang saat import.
A15: Teks biru | B15: Data contoh / isian user
A16: Komentar di header | B16: Arahkan kursor ke header untuk melihat penjelasan kolom.
A18: Sheet
A19: Sheet | B19: Isi | C19: Penghubung
A20: Vendor | B20: Master vendor | C20: Kode Vendor
A21: Pekerjaan | B21: Satu baris per pengadaan | C21: Ref Baris (baru) / Kode Pekerjaan (update)
A22: Memo | B22: Memo pengajuan & semua MoA | C22: Ref Pekerjaan
A23: RFQ | B23: RFQ + LoA (Tender/Bidding) | C23: Ref Pekerjaan (1 pekerjaan = 1 RFQ)
A24: PVP | B24: Data PVP Forum | C24: Ref Pekerjaan (1 pekerjaan = 1 PVP)
A25: PVP_Approval | B25: Approval direktur per PVP | C25: Ref Pekerjaan
A26: Approval_Pejabat | B26: Approval pejabat (PL & PK) | C26: Ref Pekerjaan
A27: PO | B27: Purchase Order | C27: Ref Pekerjaan; No. PO
A28: PO_TOP | B28: Term of payment per PO | C28: No. PO
A29: Agreement | B29: Kontrak/agreement | C29: Ref Pekerjaan; No. PO; Kode Vendor
A30: Addendum | B30: Addendum agreement | C30: No. Agreement; Ref Pekerjaan
A32: Aturan validasi
A33: Level | B33: Kondisi | C33: Akibat
A34: ERROR | B34: Kolom wajib kosong, format tanggal/angka salah, nilai tidak ada di daftar | C34: Baris ditolak
A35: ERROR | B35: Nomor dokumen ganda (memo, RFQ, LoA, PO, agreement, addendum) | C35: Baris ditolak (jika sudah ada di sistem: data di-update)
A36: ERROR | B36: Ref Pekerjaan / No. PO / Kode Vendor / No. Agreement tidak ditemukan | C36: Baris ditolak
A37: PERINGATAN | B37: PO tanpa MoA sesuai metode atau tanpa MoA Biaya | C37: Masuk, ditandai belum lengkap
A38: PERINGATAN | B38: PVP wajib (nilai > 500 jt dan kenaikan > 5%, atau pengadaan baru > 500 jt) tetapi tidak ada data PVP / approval < 2 direktur | C38: Masuk, ditandai belum lengkap
A39: PERINGATAN | B39: Metode tidak cocok dengan ambang nilai (Tender > Rp1 M, Bidding ≤ Rp1 M) | C39: Masuk, ditandai
A40: PERINGATAN | B40: PK tanpa No. Agreement Sumber atau tanpa Hasil PK | C40: Masuk, ditandai belum lengkap
A42: Daftar nilai (label di Excel → kode sistem)
A43: Kolom | B43: Label di Excel | C43: Kode sistem
A44: Jenis Pengadaan | B44: Renewal License | C44: RENEWAL_LICENSE
B45: New License | C45: NEW_LICENSE
...

Sheet Vendor
A1: Kode Vendor * | B1: Nama Vendor * | C1: Alamat Vendor * | D1: PIC Vendor * | E1: NPWP | F1: Email | G1: Telepon
A2: V001 | B2: PT Solusi Lisensi Nusantara | C2: Jl. Gatot Subroto Kav. 12, Jakarta Selatan | D2: Rina Kartika | E2: 0012345678901001 | F2: rina@solusilisensi.co.id | G2: 021-5551001
A3: V002 | B3: PT Cloud Data Indonesia | C3: Jl. TB Simatupang No. 8, Jakarta Selatan | D3: Bayu Saputra | E3: 0012345678902002 | F3: bayu@clouddata.co.id | G3: 021-5551002
A4: V003 | B4: PT Aplikasi Prima Teknologi | C4: Jl. Asia Afrika No. 45, Bandung | D4: Dewi Lestari | E4: 0012345678903003 | F4: dewi@aplikasiprima.co.id | G4: 022-5551003
A5: V004 | B5: PT Proteksi Data Mandiri | C5: Jl. Pemuda No. 21, Surabaya | D5: Hendra Wijaya | E5: 0012345678904004 | F5: hendra@proteksidata.co.id | G5: 031-5551004

Sheet Pekerjaan
A1: Ref Baris * | B1: Kode Pekerjaan | C1: Judul Pekerjaan * | D1: Jenis Pengadaan * | E1: Kategori * | F1: Metode Pengadaan * | G1: Tahun Pengadaan * | H1: PIC (Username) * | I1: Direktorat Peminta | J1: Kode Vendor | K1: Mata Uang * | L1: Nilai * | M1: Kurs ke IDR * | N1: Nilai IDR (otomatis) | O1: Nilai Pembelian Tahun Sebelumnya (IDR) | P1: Kenaikan % (otomatis) | Q1: Periode Mulai | R1: Periode Selesai | S1: No. Agreement Sumber (PK) | T1: Hasil PK | U1: Status Pekerjaan * | V1: Catatan
A2: R1 | C2: Renewal License Microsoft 365 E3 2024-2025 | D2: Renewal License | E2: BAU | F2: Tender | G2: 2024 | H2: andi.pratama | I2: DIR-OPS | J2: V001 | K2: IDR | L2: 4850000000 | M2: 1 | N2: =IF(OR(L2="",M2=""),"",L2*M2) -> 4850000000 | O2: 4300000000 | P2: =IF(OR(N2="",O2="",O2=0),"",(N2-O2)/O2) -> 0.12790698 | Q2: 45474 | R2: 45838 | U2: Selesai | V2: Contoh Tender dengan PVP
A3: R2 | C3: Renewal License Microsoft Entra ID P1 2026 | D3: Renewal License | E3: BAU | F3: Bidding | G3: 2026 | H3: sari.wulandari | I3: DIR-OPS | J3: V002 | K3: IDR | L3: 620000000 | M3: 1 | N3: =IF(OR(L3="",M3=""),"",L3*M3) -> 620000000 | O3: 600000000 | P3: =IF(OR(N3="",O3="",O3=0),"",(N3-O3)/O3) -> 0.033333333 | Q3: 46023 | R3: 46387 | U3: Aktif | V3: Kenaikan < 5%, PVP tidak wajib. Menunggu LoA & MoA Biaya
A4: R3 | C4: New Application Monitoring Jaringan | D4: New Application | E4: Project | F4: Penunjukan Langsung | G4: 2026 | H4: budi.santoso | I4: DIR-IT | J4: V003 | K4: USD | L4: 45000 | M4: 16250 | N4: =IF(OR(L4="",M4=""),"",L4*M4) -> 731250000 | P4: =IF(OR(N4="",O4="",O4=0),"",(N4-O4)/O4) | Q4: 46327 | R4: 46691 | U4: Aktif | V4: Pengadaan baru > 500 juta, PVP wajib. Menunggu approval pejabat
A5: R6 | C5: Lisensi Backup Software 2023-2026 | D5: New License | E5: BAU | F5: Bidding | G5: 2023 | H5: budi.santoso | I5: DIR-IT | J5: V004 | K5: IDR | L5: 800000000 | M5: 1 | N5: =IF(OR(L5="",M5=""),"",L5*M5) -> 800000000 | P5: =IF(OR(N5="",O5="",O5=0),"",(N5-O5)/O5) | Q5: 45108 | R5: 46203 | U5: Selesai | V5: Kontrak sumber untuk PK pada R4
A6: R4 | C6: Perpanjangan Khusus Lisensi Backup Software | D6: Renewal License | E6: BAU | F6: Perpanjangan Khusus | G6: 2026 | H6: budi.santoso | I6: DIR-IT | J6: V004 | K6: IDR | L6: 880000000 | M6: 1 | N6: =IF(OR(L6="",M6=""),"",L6*M6) -> 880000000 | O6: 800000000 | P6: =IF(OR(N6="",O6="",O6=0),"",(N6-O6)/O6) -> 0.1 | Q6: 46204 | R6: 46568 | S6: AGR/IT/2023/015 | T6: Addendum | U6: Selesai | V6: Contoh PK berakhir Addendum
A7: R5 | C7: Renewal License Antivirus 2015 | D7: Renewal License | E7: BAU | F7: Bidding | G7: 2015 | H7: andi.pratama | J7: V001 | K7: IDR | L7: 350000000 | M7: 1 | N7: =IF(OR(L7="",M7=""),"",L7*M7) -> 350000000 | P7: =IF(OR(N7="",O7="",O7=0),"",(N7-O7)/O7) | Q7: 42095 | R7: 42460 | U7: Selesai | V7: Data historis tanpa MoA Biaya: masuk sebagai PERINGATAN
N8: =IF(OR(L8="",M8=""),"",L8*M8) | P8: =IF(OR(N8="",O8="",O8=0),"",(N8-O8)/O8)
N9: =IF(OR(L9="",M9=""),"",L9*M9) | P9: =IF(OR(N9="",O9="",O9=0),"",(N9-O9)/O9)
N10: =IF(OR(L10="",M10=""),"",L10*M10) | P10: =IF(OR(N10="",O10="",O10=0),"",(N10-O10)/O10)
N11: =IF(OR(L11="",M11=""),"",L11*M11) | P11: =IF(OR(N11="",O11="",O11=0),"",(N11-O11)/O11)
N12: =IF(OR(L12="",M12=""),"",L12*M12) | P12: =IF(OR(N12="",O12="",O12=0),"",(N12-O12)/O12)
N13: =IF(OR(L13="",M13=""),"",L13*M13) | P13: =IF(OR(N13="",O13="",O13=0),"",(N13-O13)/O13)
N14: =IF(OR(L14="",M14=""),"",L14*M14) | P14: =IF(OR(N14="",O14="",O14=0),"",(N14-O14)/O14)
N15: =IF(OR(L15="",M15=""),"",L15*M15) | P15: =IF(OR(N15="",O15="",O15=0),"",(N15-O15)/O15)
N16: =IF(OR(L16="",M16=""),"",L16*M16) | P16: =IF(OR(N16="",O16="",O16=0),"",(N16-O16)/O16)
N17: =IF(OR(L17="",M17=""),"",L17*M17) | P17: =IF(OR(N17="",O17="",O17=0),"",(N17-O17)/O17)
N18: =IF(OR(L18="",M18=""),"",L18*M18) | P18: =IF(OR(N18="",O18="",O18=0),"",(N18-O18)/O18)
N19: =IF(OR(L19="",M19=""),"",L19*M19) | P19: =IF(OR(N19="",O19="",O19=0),"",(N19-O19)/O19)
... N200: =IF(OR(L200="",M200=""),"",L200*M200) | P200: =IF(OR(N200="",O200="",O200=0),"",(N200-O200)/O200)

Sheet Memo
A1: Ref Pekerjaan * | B1: No. Memo * | C1: Jenis Memo * | D1: Judul Memo * | E1: Tanggal Memo * | F1: Requestor Memo * | G1: Mata Uang | H1: Nilai | I1: Kurs ke IDR | J1: Catatan
A2: R1 | B2: 021/MEMO/IT-SAPM/II/2024 | C2: Memo Pengadaan | D2: Pengadaan Renewal Microsoft 365 E3 | E2: 45334 | F2: Andi Pratama | G2: IDR | H2: 4850000000 | I2: 1
A3: R1 | B3: 048/MOA/IT-SAPM/V/2024 | C3: MoA Hasil Tender | D3: MoA Hasil Tender Microsoft 365 E3 | E3: 45432 | F3: Andi Pratama
A4: R1 | B4: 049/MOA/IT-SAPM/V/2024 | C4: MoA Biaya | D4: MoA Biaya Microsoft 365 E3 | E4: 45434 | F4: Andi Pratama | G4: IDR | H4: 4850000000 | I4: 1
A5: R2 | B5: 007/MEMO/IT-SAPM/I/2026 | C5: Memo Pengadaan | D5: Pengadaan Renewal Entra ID P1 | E5: 46037 | F5: Sari Wulandari | G5: IDR | H5: 620000000 | I5: 1
A6: R2 | B6: 061/MOA/IT-SAPM/IX/2026 | C6: MoA Hasil Tender | D6: MoA Hasil Bidding Entra ID P1 | E6: 46283 | F6: Sari Wulandari | J6: MoA Biaya belum ada, PO belum bisa dicatat
A7: R3 | B7: 072/MEMO/IT-SAPM/IX/2026 | C7: Memo PL | D7: Penunjukan Langsung Aplikasi Monitoring Jaringan | E7: 46267 | F7: Budi Santoso | G7: USD | H7: 45000 | I7: 16250
A8: R6 | B8: 033/MEMO/IT-SAPM/III/2023 | C8: Memo Pengadaan | D8: Pengadaan Lisensi Backup Software | E8: 44991 | F8: Budi Santoso | G8: IDR | H8: 800000000 | I8: 1
A9: R6 | B9: 051/MOA/IT-SAPM/V/2023 | C9: MoA Hasil Tender | D9: MoA Hasil Bidding Lisensi Backup | E9: 45061 | F9: Budi Santoso
A10: R6 | B10: 052/MOA/IT-SAPM/V/2023 | C10: MoA Biaya | D10: MoA Biaya Lisensi Backup | E10: 45062 | F10: Budi Santoso | G10: IDR | H10: 800000000 | I10: 1
A11: R4 | B11: 015/MEMO/IT-SAPM/III/2026 | C11: Memo PK | D11: Perpanjangan Khusus Lisensi Backup Software | E11: 46091 | F11: Budi Santoso | G11: IDR | H11: 880000000 | I11: 1
A12: R4 | B12: 040/MOA/IT-SAPM/V/2026 | C12: MoA PK | D12: MoA Perpanjangan Khusus Lisensi Backup | E12: 46153 | F12: Budi Santoso
A13: R4 | B13: 041/MOA/IT-SAPM/V/2026 | C13: MoA Biaya | D13: MoA Biaya Perpanjangan Lisensi Backup | E13: 46153 | F13: Budi Santoso | G13: IDR | H13: 880000000 | I13: 1
A14: R5 | B14: 012/MEMO/IT/II/2015 | C14: Memo Pengadaan | D14: Pengadaan Renewal Antivirus | E14: 42044 | F14: Andi Pratama | G14: IDR | H14: 350000000 | I14: 1
A15: R5 | B15: 019/MOA/IT/III/2015 | C15: MoA Hasil Tender | D15: MoA Hasil Bidding Antivirus | E15: 42073 | F15: Andi Pratama | J15: Tidak ada MoA Biaya (data lama)

Sheet RFQ
A1: Ref Pekerjaan * | B1: No. RFQ * | C1: Metode * | D1: Periode Mulai | E1: Periode Selesai | F1: Mata Uang | G1: Nilai | H1: Kurs ke IDR | I1: Term of Payment | J1: No. LoA | K1: Tanggal LoA | L1: LoA Diproses Oleh
A2: R1 | B2: RFQ/IT/2024/003 | C2: Tender | D2: 45474 | E2: 45838 | F2: IDR | G2: 4850000000 | H2: 1 | I2: 100% setelah lisensi aktif | J2: LOA/PROC/2024/017 | K2: 45439 | L2: Procurement
A3: R2 | B3: RFQ/IT/2026/011 | C3: Bidding | D3: 46023 | E3: 46387 | F3: IDR | G3: 620000000 | H3: 1 | I3: 100% setelah lisensi aktif | L3: Procurement
A4: R6 | B4: RFQ/IT/2023/009 | C4: Bidding | D4: 45108 | E4: 46203 | F4: IDR | G4: 800000000 | H4: 1 | I4: Tahunan, 3 termin | J4: LOA/PROC/2023/021 | K4: 45065 | L4: Procurement
A5: R5 | B5: RFQ/IT/2015/004 | C5: Bidding | D5: 42095 | E5: 42460 | F5: IDR | G5: 350000000 | H5: 1 | I5: 100% di muka | J5: LOA/PROC/2015/006 | K5: 42075 | L5: Procurement

Sheet PVP
A1: Ref Pekerjaan * | B1: Tanggal PVP * | C1: Status PVP * | D1: Catatan
A2: R1 | B2: 45400 | C2: Disetujui | D2: Kenaikan 12,79% dari 2023
A3: R3 | B3: 46289 | C3: Disetujui | D3: Pengadaan baru > 500 juta
A4: R4 | B4: 46114 | C4: Disetujui | D4: Kenaikan 10% dari kontrak 2023

Sheet PVP_Approval
A1: Ref Pekerjaan * | B1: Nama Direktur * | C1: Keputusan * | D1: Tanggal Approval * | E1: Catatan
A2: R1 | B2: Direktur Operasional | C2: Disetujui | D2: 45401
A3: R1 | B3: Direktur Keuangan | C3: Disetujui | D3: 45404
A4: R1 | B4: Direktur IT | C4: Disetujui | D4: 45404
A5: R3 | B5: Direktur IT | C5: Disetujui | D5: 46290
A6: R3 | B6: Direktur Keuangan | C6: Disetujui | D6: 46294
A7: R4 | B7: Direktur IT | C7: Disetujui | D7: 46115
A8: R4 | B8: Direktur Keuangan | C8: Disetujui | D8: 46118

Sheet Approval_Pejabat
A1: Ref Pekerjaan * | B1: Nama Pejabat * | C1: Jabatan | D1: No. Referensi | E1: Tanggal Approval | F1: Catatan
A2: R4 | B2: Hartono Wibisono | C2: VP Procurement | D2: DISP/PROC/2026/031 | E2: 46132
A3: R3 | B3: Hartono Wibisono | C3: VP Procurement | F3: Diajukan 01/10/2026, belum ada keputusan

Sheet PO
A1: Ref Pekerjaan * | B1: No. PO * | C1: Tipe PO * | D1: Nama PO * | E1: Tanggal PO * | F1: Mata Uang * | G1: Nilai PO * | H1: Kurs ke IDR * | I1: Nilai IDR (otomatis) | J1: Requestor PO | K1: No. PO Sebelumnya | L1: Nilai PO Sebelumnya | M1: Mata Uang PO Sebelumnya
A2: R1 | B2: 4500123401 | C2: Renewal | D2: Microsoft 365 E3 2024-2025 | E2: 45453 | F2: IDR | G2: 4850000000 | H2: 1 | I2: =IF(OR(G2="",H2=""),"",G2*H2) -> 4850000000 | J2: Andi Pratama | K2: 4500118820 | L2: 4300000000 | M2: IDR
A3: R6 | B3: 4500107715 | C3: New | D3: Lisensi Backup Software 2023-2026 | E3: 45082 | F3: IDR | G3: 800000000 | H3: 1 | I3: =IF(OR(G3="",H3=""),"",G3*H3) -> 800000000 | J3: Budi Santoso
A4: R4 | B4: 4500131190 | C4: Renewal | D4: Perpanjangan Lisensi Backup 2026-2027 | E4: 46167 | F4: IDR | G4: 880000000 | H4: 1 | I4: =IF(OR(G4="",H4=""),"",G4*H4) -> 880000000 | J4: Budi Santoso | K4: 4500107715 | L4: 800000000 | M4: IDR
A5: R5 | B5: 4500021187 | C5: Renewal | D5: Renewal Antivirus 2015 | E5: 42083 | F5: IDR | G5: 350000000 | H5: 1 | I5: =IF(OR(G5="",H5=""),"",G5*H5) -> 350000000 | J5: Andi Pratama
I6: =IF(OR(G6="",H6=""),"",G6*H6)
I7: =IF(OR(G7="",H7=""),"",G7*H7)
I8: =IF(OR(G8="",H8=""),"",G8*H8)
I9: =IF(OR(G9="",H9=""),"",G9*H9)
I10: =IF(OR(G10="",H10=""),"",G10*H10)
I11: =IF(OR(G11="",H11=""),"",G11*H11)
I12: =IF(OR(G12="",H12=""),"",G12*H12)
I13: =IF(OR(G13="",H13=""),"",G13*H13)
I14: =IF(OR(G14="",H14=""),"",G14*H14)
I15: =IF(OR(G15="",H15=""),"",G15*H15)
I16: =IF(OR(G16="",H16=""),"",G16*H16)
I17: =IF(OR(G17="",H17=""),"",G17*H17)
... I200: =IF(OR(G200="",H200=""),"",G200*H200)

Sheet PO_TOP
A1: No. PO * | B1: Urutan * | C1: Deskripsi * | D1: Persentase | E1: Nilai Termin (otomatis) | F1: Jatuh Tempo | G1: Sudah Dibayar
A2: 4500123401 | B2: 1 | C2: Pembayaran penuh setelah lisensi aktif | D2: 1 | E2: =IF(OR(A2="",D2=""),"",IFERROR(D2*INDEX(PO!$G$2:$G$1000,MATCH(A2,PO!$B$2:$B$1000,0)),"")) -> 4850000000 | F2: 45504 | G2: Ya
A3: 4500107715 | B3: 1 | C3: Termin 1 tahun 2023 | D3: 0.3333 | E3: =IF(OR(A3="",D3=""),"",IFERROR(D3*INDEX(PO!$G$2:$G$1000,MATCH(A3,PO!$B$2:$B$1000,0)),"")) -> 266640000 | F3: 45138 | G3: Ya
A4: 4500107715 | B4: 2 | C4: Termin 2 tahun 2024 | D4: 0.3333 | E4: =IF(OR(A4="",D4=""),"",IFERROR(D4*INDEX(PO!$G$2:$G$1000,MATCH(A4,PO!$B$2:$B$1000,0)),"")) -> 266640000 | F4: 45504 | G4: Ya
A5: 4500107715 | B5: 3 | C5: Termin 3 tahun 2025 | D5: 0.3334 | E5: =IF(OR(A5="",D5=""),"",IFERROR(D5*INDEX(PO!$G$2:$G$1000,MATCH(A5,PO!$B$2:$B$1000,0)),"")) -> 266720000 | F5: 45869 | G5: Ya
A6: 4500131190 | B6: 1 | C6: Pembayaran penuh setelah perpanjangan aktif | D6: 1 | E6: =IF(OR(A6="",D6=""),"",IFERROR(D6*INDEX(PO!$G$2:$G$1000,MATCH(A6,PO!$B$2:$B$1000,0)),"")) -> 880000000 | F6: 46234 | G6: Tidak
E7: =IF(OR(A7="",D7=""),"",IFERROR(D7*INDEX(PO!$G$2:$G$1000,MATCH(A7,PO!$B$2:$B$1000,0)),""))
E8: =IF(OR(A8="",D8=""),"",IFERROR(D8*INDEX(PO!$G$2:$G$1000,MATCH(A8,PO!$B$2:$B$1000,0)),""))
E9: =IF(OR(A9="",D9=""),"",IFERROR(D9*INDEX(PO!$G$2:$G$1000,MATCH(A9,PO!$B$2:$B$1000,0)),""))
E10: =IF(OR(A10="",D10=""),"",IFERROR(D10*INDEX(PO!$G$2:$G$1000,MATCH(A10,PO!$B$2:$B$1000,0)),""))
E11: =IF(OR(A11="",D11=""),"",IFERROR(D11*INDEX(PO!$G$2:$G$1000,MATCH(A11,PO!$B$2:$B$1000,0)),""))
E12: =IF(OR(A12="",D12=""),"",IFERROR(D12*INDEX(PO!$G$2:$G$1000,MATCH(A12,PO!$B$2:$B$1000,0)),""))
E13: =IF(OR(A13="",D13=""),"",IFERROR(D13*INDEX(PO!$G$2:$G$1000,MATCH(A13,PO!$B$2:$B$1000,0)),""))
E14: =IF(OR(A14="",D14=""),"",IFERROR(D14*INDEX(PO!$G$2:$G$1000,MATCH(A14,PO!$B$2:$B$1000,0)),""))
E15: =IF(OR(A15="",D15=""),"",IFERROR(D15*INDEX(PO!$G$2:$G$1000,MATCH(A15,PO!$B$2:$B$1000,0)),""))
E16: =IF(OR(A16="",D16=""),"",IFERROR(D16*INDEX(PO!$G$2:$G$1000,MATCH(A16,PO!$B$2:$B$1000,0)),""))
E17: =IF(OR(A17="",D17=""),"",IFERROR(D17*INDEX(PO!$G$2:$G$1000,MATCH(A17,PO!$B$2:$B$1000,0)),""))
E18: =IF(OR(A18="",D18=""),"",IFERROR(D18*INDEX(PO!$G$2:$G$1000,MATCH(A18,PO!$B$2:$B$1000,0)),""))
... E200: =IF(OR(A200="",D200=""),"",IFERROR(D200*INDEX(PO!$G$2:$G$1000,MATCH(A200,PO!$B$2:$B$1000,0)),""))

Sheet Agreement
A1: Ref Pekerjaan * | B1: No. Agreement * | C1: Tipe Agreement * | D1: Judul Agreement * | E1: Kode Vendor * | F1: No. PO * | G1: PIC (Username) * | H1: Periode Mulai * | I1: Periode Selesai * | J1: Mata Uang * | K1: Nilai * | L1: Kurs ke IDR * | M1: Nilai IDR (otomatis)
A2: R1 | B2: AGR/IT/2024/008 | C2: Renewal | D2: Perjanjian Lisensi Microsoft 365 E3 2024-2025 | E2: V001 | F2: 4500123401 | G2: andi.pratama | H2: 45474 | I2: 45838 | J2: IDR | K2: 4850000000 | L2: 1 | M2: =IF(OR(K2="",L2=""),"",K2*L2) -> 4850000000
A3: R6 | B3: AGR/IT/2023/015 | C3: New | D3: Perjanjian Lisensi Backup Software | E3: V004 | F3: 4500107715 | G3: budi.santoso | H3: 45108 | I3: 46203 | J3: IDR | K3: 800000000 | L3: 1 | M3: =IF(OR(K3="",L3=""),"",K3*L3) -> 800000000
A4: R5 | B4: AGR/IT/2015/003 | C4: Renewal | D4: Perjanjian Lisensi Antivirus 2015 | E4: V001 | F4: 4500021187 | G4: andi.pratama | H4: 42095 | I4: 42460 | J4: IDR | K4: 350000000 | L4: 1 | M4: =IF(OR(K4="",L4=""),"",K4*L4) -> 350000000
M5: =IF(OR(K5="",L5=""),"",K5*L5)
M6: =IF(OR(K6="",L6=""),"",K6*L6)
M7: =IF(OR(K7="",L7=""),"",K7*L7)
M8: =IF(OR(K8="",L8=""),"",K8*L8)
M9: =IF(OR(K9="",L9=""),"",K9*L9)
M10: =IF(OR(K10="",L10=""),"",K10*L10)
M11: =IF(OR(K11="",L11=""),"",K11*L11)
M12: =IF(OR(K12="",L12=""),"",K12*L12)
M13: =IF(OR(K13="",L13=""),"",K13*L13)
M14: =IF(OR(K14="",L14=""),"",K14*L14)
M15: =IF(OR(K15="",L15=""),"",K15*L15)
M16: =IF(OR(K16="",L16=""),"",K16*L16)
... M200: =IF(OR(K200="",L200=""),"",K200*L200)

Sheet Addendum
A1: No. Agreement * | B1: Ref Pekerjaan * | C1: No. Addendum * | D1: Judul Addendum * | E1: Tanggal Addendum * | F1: Periode Selesai Baru | G1: Perubahan Nilai | H1: Mata Uang | I1: No. PO Terkait | J1: Catatan
A2: AGR/IT/2023/015 | B2: R4 | C2: ADD-01/AGR/IT/2023/015 | D2: Addendum I Perpanjangan Lisensi Backup Software | E2: 46188 | F2: 46568 | G2: 880000000 | H2: IDR | I2: 4500131190

Sheet Daftar
A1: Jenis | B1: Kategori | C1: Metode | D1: MetodeRFQ | E1: StatusPekerjaan | F1: HasilPK | G1: JenisMemo | H1: StatusPVP | I1: Keputusan | J1: Tipe | K1: MataUang | L1: YaTidak
A2: Renewal License | B2: BAU | C2: Tender | D2: Tender | E2: Aktif | F2: Addendum | G2: Memo Pengadaan | H2: Menunggu | I2: Disetujui | J2: New | K2: IDR | L2: Ya
A3: New License | B3: Project | C3: Bidding | D3: Bidding | E3: Ditunda | F3: Agreement Baru | G3: Memo PL | H3: Disetujui | I3: Ditolak | J3: Renewal | K3: USD | L3: Tidak
A4: New Application | C4: Perpanjangan Khusus | E4: Selesai | G4: Memo PK | H4: Ditolak | K4: SGD
C5: Penunjukan Langsung | E5: Dibatalkan | G5: MoA Hasil Tender | K5: EUR
G6: MoA PL
G7: MoA PK
G8: MoA Biaya
